Workbook

Sheet Permissions
A1: Clinic user permissions — full list
A2: Draft for review · 28 October 2026 · Each colour is one module. Role columns show default access: Own = user’s own sessions · Assigned = clients and therapists assigned to the user · Clinic = whole clinic · — = not granted. Status: Agreed = in PRD, agreed flows or FSD · Pending = raised, not confirmed · Proposed = suggested to close a gap.
A4: ID | B4: Module | C4: Permission | D4: What it allows | E4: Level | F4: Therapist | G4: Supervisor (BCBA) | H4: Org Admin | I4: Scheduler (pending) | J4: Contains PHI | K4: Admin access (MFA mandatory) | L4: Password re-entry | M4: Audit logged | N4: Depends on | O4: Status | P4: Source
A5: My account · 5 permissions
A6: ACC-01 | B6: My account | C6: Log in and log out | D6: Sign in with email and password; sign out | E6: Always on | F6: Own | G6: Own | H6: Own | I6: Own | J6: No | K6: No | L6: No | M6: Yes | N6: — | O6: Agreed | P6: FSD v0.3 S5; PRD 8.1
A7: ACC-02 | B7: My account | C7: Change or reset own password | D7: Set a new password at first login; reset through Forgot password | E7: Always on | F7: Own | G7: Own | H7: Own | I7: Own | J7: No | K7: No | L7: No | M7: Yes | N7: — | O7: Agreed | P7: FSD v0.3 S6, S8
A8: ACC-03 | B8: My account | C8: Enter email code at login | D8: Complete MFA when required for the user | E8: Always on | F8: Own | G8: Own | H8: Own | I8: Own | J8: No | K8: No | L8: No | M8: Yes | N8: MFA on for the user | O8: Agreed | P8: FSD v0.3 S7, BR-11
A9: ACC-04 | B9: My account | C9: View own notifications | D9: Reminders, supervisor notes and tasks, alerts addressed to the user | E9: Always on | F9: Own | G9: Own | H9: Own | I9: Own | J9: Yes | K9: No | L9: No | M9: No | N9: — | O9: Agreed | P9: Therapist flow draft; PRD 8.6
A10: ACC-05 | B10: My account | C10: View own profile and permissions | D10: See own details, role and the modules granted | E10: Always on | F10: Own | G10: Own | H10: Own | I10: Own | J10: No | K10: No | L10: No | M10: No | N10: — | O10: Proposed | P10: Not yet in flows
A11: Dashboard · 4 permissions
A12: DSH-01 | B12: Dashboard | C12: View therapist dashboard | D12: Today’s sessions, pending items, summaries ready, notes and tasks from the supervisor | E12: View | F12: Own | G12: — | H12: — | I12: — | J12: Yes | K12: No | L12: No | M12: No | N12: — | O12: Agreed | P12: Therapist flow; PRD 8.7
A13: DSH-02 | B13: Dashboard | C13: View caseload dashboard | D13: Caseload overview, flagged sessions, trend summaries | E13: View | F13: — | G13: Assigned | H13: — | I13: — | J13: Yes | K13: No | L13: No | M13: No | N13: — | O13: Agreed | P13: Supervisor flow D-013; PRD 8.7
A14: DSH-03 | B14: Dashboard | C14: View organization dashboard | D14: Active users, active clients, locations, pending actions, license use | E14: View | F14: — | G14: — | H14: Clinic | I14: — | J14: No | K14: No | L14: No | M14: No | N14: — | O14: Agreed | P14: PRD 8.7
A15: DSH-04 | B15: Dashboard | C15: View trends with detail on hover | D15: Trend charts by default; exact values shown on hover | E15: View | F15: Own | G15: Assigned | H15: — | I15: — | J15: Yes | K15: No | L15: No | M15: No | N15: — | O15: Agreed | P15: Review meeting 22 Oct
A16: Sessions · 20 permissions
A17: SES-01 | B17: Sessions | C17: View session schedule | D17: See scheduled sessions and their status | E17: View | F17: Own | G17: Assigned | H17: Clinic | I17: Clinic | J17: Yes | K17: No | L17: No | M17: No | N17: — | O17: Agreed | P17: PRD 8.2
A18: SES-02 | B18: Sessions | C18: Create a session | D18: Schedule a session for a client and therapist | E18: Edit | F18: — | G18: Assigned | H18: Clinic | I18: Clinic | J18: Yes | K18: No | L18: No | M18: Yes | N18: — | O18: Pending | P18: Review meeting 22 Oct: Scheduler or BCBA to be confirmed
A19: SES-03 | B19: Sessions | C19: Reschedule or edit a session | D19: Change date, time, therapist or session type | E19: Edit | F19: — | G19: Assigned | H19: Clinic | I19: Clinic | J19: Yes | K19: No | L19: No | M19: Yes | N19: — | O19: Pending | P19: As SES-02
A20: SES-04 | B20: Sessions | C20: Cancel a session or mark a no-show | D20: With a reason; nothing is sent to the AI vendor | E20: Edit | F20: Own | G20: Assigned | H20: Clinic | I20: Clinic | J20: Yes | K20: No | L20: No | M20: Yes | N20: — | O20: Agreed | P20: Therapist flow D-017
A21: SES-05 | B21: Sessions | C21: Bulk import sessions (CSV) | D21: Upload a schedule file, fix errors, confirm | E21: Edit | F21: — | G21: — | H21: Clinic | I21: Clinic | J21: Yes | K21: No | L21: No | M21: Yes | N21: — | O21: Agreed | P21: PRD 8.2; Org Admin flow D-014
A22: SES-06 | B22: Sessions | C22: Start an in-person session | D22: Starts monitoring; wearable and audio device linked | E22: Edit | F22: Own | G22: — | H22: — | I22: — | J22: Yes | K22: No | L22: No | M22: Yes | N22: Valid consent; current assessment | O22: Agreed | P22: Therapist flow
A23: SES-07 | B23: Sessions | C23: Start an online session | D23: Sends the parent a guest link; call recorded automatically | E23: Edit | F23: Own | G23: — | H23: — | I23: — | J23: Yes | K23: No | L23: No | M23: Yes | N23: Telehealth enabled on license; consent | O23: Agreed | P23: Therapist flow; PRD 17
A24: SES-08 | B24: Sessions | C24: Pause and resume a session | D24: Pause is marked in the timeline; alert after the set time | E24: Edit | F24: Own | G24: — | H24: — | I24: — | J24: No | K24: No | L24: No | M24: Yes | N24: — | O24: Agreed | P24: Therapist flow draft 18 Oct
A25: SES-09 | B25: Sessions | C25: Pause and resume the call recording | D25: Online sessions only; call continues | E25: Edit | F25: Own | G25: — | H25: — | I25: — | J25: No | K25: No | L25: No | M25: Yes | N25: Online session | O25: Agreed | P25: Therapist flow 15 Oct
A26: SES-10 | B26: Sessions | C26: End a session | D26: Manual end; the system also ends it at window close | E26: Edit | F26: Own | G26: — | H26: — | I26: — | J26: No | K26: No | L26: No | M26: Yes | N26: — | O26: Agreed | P26: Therapist flow
A27: SES-11 | B27: Sessions | C27: Tick checklist items | D27: Time-stamped; items cannot be added or removed | E27: Edit | F27: Own | G27: — | H27: — | I27: — | J27: Yes | K27: No | L27: No | M27: Yes | N27: — | O27: Agreed | P27: Therapist flow D-017
A28: SES-12 | B28: Sessions | C28: Add notes, observations and markers | D28: Typed on screen during the session | E28: Edit | F28: Own | G28: — | H28: — | I28: — | J28: Yes | K28: No | L28: No | M28: Yes | N28: — | O28: Agreed | P28: PRD 8.3; review meeting 22 Oct
... A36: SES-20 | B36: Sessions | C36: Watch a live session in progress | D36: Supervisor view of an ongoing session | E36: View | F36: — | G36: — | H36: — | I36: — | J36: Yes | K36: No | L36: No | M36: Yes | N36: — | O36: Proposed | P36: Not yet in flows
A37: Summaries · 4 permissions
A38: SUM-01 | B38: Summaries | C38: View AI summary | D38: Visible as soon as it is generated | E38: View | F38: Own | G38: Assigned | H38: — | I38: — | J38: Yes | K38: No | L38: No | M38: No | N38: — | O38: Agreed | P38: Therapist flow draft 15 Oct
A39: SUM-02 | B39: Summaries | C39: Add therapist note to the summary | D39: The summary itself cannot be edited | E39: Edit | F39: Own | G39: — | H39: — | I39: — | J39: Yes | K39: No | L39: No | M39: Yes | N39: — | O39: Agreed | P39: Therapist flow draft 15 Oct
A40: SUM-03 | B40: Summaries | C40: Retry summary generation | D40: After a failure or timeout | E40: Edit | F40: Own | G40: — | H40: — | I40: — | J40: Yes | K40: No | L40: No | M40: Yes | N40: — | O40: Agreed | P40: PRD 8.8
A41: SUM-04 | B41: Summaries | C41: Write the summary manually | D41: Only when generation keeps failing; labeled as written by the therapist | E41: Edit | F41: Own | G41: — | H41: — | I41: — | J41: Yes | K41: No | L41: No | M41: Yes | N41: — | O41: Agreed | P41: Therapist flow draft 15 Oct
A42: Supervision · 7 permissions
A43: SPV-01 | B43: Supervision | C43: View flagged sessions | D43: Sessions with alerts, most alerts first | E43: View | F43: — | G43: Assigned | H43: — | I43: — | J43: Yes | K43: No | L43: No | M43: No | N43: — | O43: Agreed | P43: Supervisor flow D-013
A44: SPV-02 | B44: Supervision | C44: Compare sessions side by side | D44: Across sessions of a client | E44: View | F44: — | G44: Assigned | H44: — | I44: — | J44: Yes | K44: No | L44: No | M44: No | N44: — | O44: Agreed | P44: PRD 8.8
A45: SPV-03 | B45: Supervision | C45: Mark a session reviewed | D45: Logged for audit | E45: Edit | F45: — | G45: Assigned | H45: — | I45: — | J45: Yes | K45: No | L45: No | M45: Yes | N45: — | O45: Agreed | P45: Supervisor flow D-013
A46: SPV-04 | B46: Supervision | C46: Add a note or task for a therapist | D46: Sent to the therapist’s dashboard | E46: Edit | F46: — | G46: Assigned | H46: — | I46: — | J46: Yes | K46: No | L46: No | M46: Yes | N46: — | O46: Agreed | P46: Supervisor flow D-013
A47: SPV-05 | B47: Supervision | C47: Remind a therapist | D47: About pending items | E47: Edit | F47: — | G47: Assigned | H47: — | I47: — | J47: No | K47: No | L47: No | M47: Yes | N47: — | O47: Agreed | P47: Supervisor flow D-013
A48: SPV-06 | B48: Supervision | C48: Approve clinical documentation | D48: Where permitted | E48: Edit | F48: — | G48: Assigned | H48: — | I48: — | J48: Yes | K48: No | L48: No | M48: Yes | N48: — | O48: Pending | P48: Open question Q-19
...

Sheet Role summary
A1: Default permissions per role, by module
A2: Counts of permissions each role gets by default (anything other than —). Updates when the Permissions sheet changes.
A4: Module | B4: Permissions | C4: Therapist | D4: Supervisor (BCBA) | E4: Org Admin | F4: Scheduler (pending) | G4: Admin access module
A5: My account | B5: =COUNTIF(Permissions!$B$5:$B$500,$A5) -> 5 | C5: =COUNTIFS(Permissions!$B$5:$B$500,$A5,Permissions!$F$5:$F$500,"<>—") -> 5 | D5: =COUNTIFS(Permissions!$B$5:$B$500,$A5,Permissions!$G$5:$G$500,"<>—") -> 5 | E5: =COUNTIFS(Permissions!$B$5:$B$500,$A5,Permissions!$H$5:$H$500,"<>—") -> 5 | F5: =COUNTIFS(Permissions!$B$5:$B$500,$A5,Permissions!$I$5:$I$500,"<>—") -> 5 | G5: =IF(COUNTIFS(Permissions!$B$5:$B$500,$A5,Permissions!$K$5:$K$500,"Yes")>0,"Yes","No") -> No
A6: Dashboard | B6: =COUNTIF(Permissions!$B$5:$B$500,$A6) -> 4 | C6: =COUNTIFS(Permissions!$B$5:$B$500,$A6,Permissions!$F$5:$F$500,"<>—") -> 2 | D6: =COUNTIFS(Permissions!$B$5:$B$500,$A6,Permissions!$G$5:$G$500,"<>—") -> 2 | E6: =COUNTIFS(Permissions!$B$5:$B$500,$A6,Permissions!$H$5:$H$500,"<>—") -> 1 | F6: =COUNTIFS(Permissions!$B$5:$B$500,$A6,Permissions!$I$5:$I$500,"<>—") -> 0 | G6: =IF(COUNTIFS(Permissions!$B$5:$B$500,$A6,Permissions!$K$5:$K$500,"Yes")>0,"Yes","No") -> No
A7: Sessions | B7: =COUNTIF(Permissions!$B$5:$B$500,$A7) -> 20 | C7: =COUNTIFS(Permissions!$B$5:$B$500,$A7,Permissions!$F$5:$F$500,"<>—") -> 15 | D7: =COUNTIFS(Permissions!$B$5:$B$500,$A7,Permissions!$G$5:$G$500,"<>—") -> 7 | E7: =COUNTIFS(Permissions!$B$5:$B$500,$A7,Permissions!$H$5:$H$500,"<>—") -> 5 | F7: =COUNTIFS(Permissions!$B$5:$B$500,$A7,Permissions!$I$5:$I$500,"<>—") -> 5 | G7: =IF(COUNTIFS(Permissions!$B$5:$B$500,$A7,Permissions!$K$5:$K$500,"Yes")>0,"Yes","No") -> No
A8: Summaries | B8: =COUNTIF(Permissions!$B$5:$B$500,$A8) -> 4 | C8: =COUNTIFS(Permissions!$B$5:$B$500,$A8,Permissions!$F$5:$F$500,"<>—") -> 4 | D8: =COUNTIFS(Permissions!$B$5:$B$500,$A8,Permissions!$G$5:$G$500,"<>—") -> 1 | E8: =COUNTIFS(Permissions!$B$5:$B$500,$A8,Permissions!$H$5:$H$500,"<>—") -> 0 | F8: =COUNTIFS(Permissions!$B$5:$B$500,$A8,Permissions!$I$5:$I$500,"<>—") -> 0 | G8: =IF(COUNTIFS(Permissions!$B$5:$B$500,$A8,Permissions!$K$5:$K$500,"Yes")>0,"Yes","No") -> No
A9: Supervision | B9: =COUNTIF(Permissions!$B$5:$B$500,$A9) -> 7 | C9: =COUNTIFS(Permissions!$B$5:$B$500,$A9,Permissions!$F$5:$F$500,"<>—") -> 1 | D9: =COUNTIFS(Permissions!$B$5:$B$500,$A9,Permissions!$G$5:$G$500,"<>—") -> 6 | E9: =COUNTIFS(Permissions!$B$5:$B$500,$A9,Permissions!$H$5:$H$500,"<>—") -> 0 | F9: =COUNTIFS(Permissions!$B$5:$B$500,$A9,Permissions!$I$5:$I$500,"<>—") -> 0 | G9: =IF(COUNTIFS(Permissions!$B$5:$B$500,$A9,Permissions!$K$5:$K$500,"Yes")>0,"Yes","No") -> No
A10: Clients | B10: =COUNTIF(Permissions!$B$5:$B$500,$A10) -> 8 | C10: =COUNTIFS(Permissions!$B$5:$B$500,$A10,Permissions!$F$5:$F$500,"<>—") -> 1 | D10: =COUNTIFS(Permissions!$B$5:$B$500,$A10,Permissions!$G$5:$G$500,"<>—") -> 2 | E10: =COUNTIFS(Permissions!$B$5:$B$500,$A10,Permissions!$H$5:$H$500,"<>—") -> 8 | F10: =COUNTIFS(Permissions!$B$5:$B$500,$A10,Permissions!$I$5:$I$500,"<>—") -> 1 | G10: =IF(COUNTIFS(Permissions!$B$5:$B$500,$A10,Permissions!$K$5:$K$500,"Yes")>0,"Yes","No") -> No
A11: Assessments | B11: =COUNTIF(Permissions!$B$5:$B$500,$A11) -> 4 | C11: =COUNTIFS(Permissions!$B$5:$B$500,$A11,Permissions!$F$5:$F$500,"<>—") -> 2 | D11: =COUNTIFS(Permissions!$B$5:$B$500,$A11,Permissions!$G$5:$G$500,"<>—") -> 4 | E11: =COUNTIFS(Permissions!$B$5:$B$500,$A11,Permissions!$H$5:$H$500,"<>—") -> 1 | F11: =COUNTIFS(Permissions!$B$5:$B$500,$A11,Permissions!$I$5:$I$500,"<>—") -> 0 | G11: =IF(COUNTIFS(Permissions!$B$5:$B$500,$A11,Permissions!$K$5:$K$500,"Yes")>0,"Yes","No") -> No
A12: Consent | B12: =COUNTIF(Permissions!$B$5:$B$500,$A12) -> 4 | C12: =COUNTIFS(Permissions!$B$5:$B$500,$A12,Permissions!$F$5:$F$500,"<>—") -> 4 | D12: =COUNTIFS(Permissions!$B$5:$B$500,$A12,Permissions!$G$5:$G$500,"<>—") -> 1 | E12: =COUNTIFS(Permissions!$B$5:$B$500,$A12,Permissions!$H$5:$H$500,"<>—") -> 4 | F12: =COUNTIFS(Permissions!$B$5:$B$500,$A12,Permissions!$I$5:$I$500,"<>—") -> 0 | G12: =IF(COUNTIFS(Permissions!$B$5:$B$500,$A12,Permissions!$K$5:$K$500,"Yes")>0,"Yes","No") -> No
A13: Devices | B13: =COUNTIF(Permissions!$B$5:$B$500,$A13) -> 2 | C13: =COUNTIFS(Permissions!$B$5:$B$500,$A13,Permissions!$F$5:$F$500,"<>—") -> 1 | D13: =COUNTIFS(Permissions!$B$5:$B$500,$A13,Permissions!$G$5:$G$500,"<>—") -> 0 | E13: =COUNTIFS(Permissions!$B$5:$B$500,$A13,Permissions!$H$5:$H$500,"<>—") -> 2 | F13: =COUNTIFS(Permissions!$B$5:$B$500,$A13,Permissions!$I$5:$I$500,"<>—") -> 0 | G13: =IF(COUNTIFS(Permissions!$B$5:$B$500,$A13,Permissions!$K$5:$K$500,"Yes")>0,"Yes","No") -> No
A14: Reports | B14: =COUNTIF(Permissions!$B$5:$B$500,$A14) -> 4 | C14: =COUNTIFS(Permissions!$B$5:$B$500,$A14,Permissions!$F$5:$F$500,"<>—") -> 0 | D14: =COUNTIFS(Permissions!$B$5:$B$500,$A14,Permissions!$G$5:$G$500,"<>—") -> 2 | E14: =COUNTIFS(Permissions!$B$5:$B$500,$A14,Permissions!$H$5:$H$500,"<>—") -> 1 | F14: =COUNTIFS(Permissions!$B$5:$B$500,$A14,Permissions!$I$5:$I$500,"<>—") -> 0 | G14: =IF(COUNTIFS(Permissions!$B$5:$B$500,$A14,Permissions!$K$5:$K$500,"Yes")>0,"Yes","No") -> No
A15: Users & roles | B15: =COUNTIF(Permissions!$B$5:$B$500,$A15) -> 11 | C15: =COUNTIFS(Permissions!$B$5:$B$500,$A15,Permissions!$F$5:$F$500,"<>—") -> 0 | D15: =COUNTIFS(Permissions!$B$5:$B$500,$A15,Permissions!$G$5:$G$500,"<>—") -> 0 | E15: =COUNTIFS(Permissions!$B$5:$B$500,$A15,Permissions!$H$5:$H$500,"<>—") -> 11 | F15: =COUNTIFS(Permissions!$B$5:$B$500,$A15,Permissions!$I$5:$I$500,"<>—") -> 0 | G15: =IF(COUNTIFS(Permissions!$B$5:$B$500,$A15,Permissions!$K$5:$K$500,"Yes")>0,"Yes","No") -> Yes
A16: Clinic settings | B16: =COUNTIF(Permissions!$B$5:$B$500,$A16) -> 9 | C16: =COUNTIFS(Permissions!$B$5:$B$500,$A16,Permissions!$F$5:$F$500,"<>—") -> 0 | D16: =COUNTIFS(Permissions!$B$5:$B$500,$A16,Permissions!$G$5:$G$500,"<>—") -> 0 | E16: =COUNTIFS(Permissions!$B$5:$B$500,$A16,Permissions!$H$5:$H$500,"<>—") -> 9 | F16: =COUNTIFS(Permissions!$B$5:$B$500,$A16,Permissions!$I$5:$I$500,"<>—") -> 0 | G16: =IF(COUNTIFS(Permissions!$B$5:$B$500,$A16,Permissions!$K$5:$K$500,"Yes")>0,"Yes","No") -> Yes
... A18: Support access | B18: =COUNTIF(Permissions!$B$5:$B$500,$A18) -> 2 | C18: =COUNTIFS(Permissions!$B$5:$B$500,$A18,Permissions!$F$5:$F$500,"<>—") -> 0 | D18: =COUNTIFS(Permissions!$B$5:$B$500,$A18,Permissions!$G$5:$G$500,"<>—") -> 0 | E18: =COUNTIFS(Permissions!$B$5:$B$500,$A18,Permissions!$H$5:$H$500,"<>—") -> 2 | F18: =COUNTIFS(Permissions!$B$5:$B$500,$A18,Permissions!$I$5:$I$500,"<>—") -> 0 | G18: =IF(COUNTIFS(Permissions!$B$5:$B$500,$A18,Permissions!$K$5:$K$500,"Yes")>0,"Yes","No") -> No
A19: Total | B19: =SUM(B5:B18) -> 86 | C19: =SUM(C5:C18) -> 35 | D19: =SUM(D5:D18) -> 30 | E19: =SUM(E5:E18) -> 50 | F19: =SUM(F5:F18) -> 11

Sheet Open points
A1: Points to confirm
A2: Decisions needed before the permission list is final
A4: # | B4: Point | C4: Affects | D4: Suggestion
A5: 1 | B5: Does a Scheduler role exist, and who creates sessions: Scheduler or BCBA? | C5: SES-02, SES-03, Scheduler column | D5: Keep both able to create; final call by BEST
A6: 2 | B6: Who selects the assessment type at client setup? | C6: ASM-03 | D6: Supervisor (BCBA), with Org Admin as backup
A7: 3 | B7: Can supervisors approve clinical documentation, and which documents? | C7: SPV-06 | D7: Close open question Q-19
A8: 4 | B8: Add three new modules: Supervision, Devices, Support access? | C8: SPV, DEV, SUP rows | D8: Yes; they cover features already agreed
A9: 5 | B9: Should anyone download attachments, export reports or export the audit log? | C9: SES-19, RPT-04, AUD-02 | D9: Allow only for Org Admin, with password re-entry
A10: 6 | B10: Should supervisors watch a live session in progress? | C10: SES-20 | D10: Not in Phase 1
A11: 7 | B11: Who links devices to clients or sessions, and can the clinic see its device list? | C11: DEV-01, DEV-02 | D11: Org Admin manages; therapist links at session start
A12: 8 | B12: Extend password re-entry to archiving clients, editing users or roles, and support-access approval? | C12: CLI-04, USR-05, USR-10, SUP-01 | D12: Yes for SUP-01; optional for the others
A13: 9 | B13: Should approving support access count as admin access (mandatory MFA)? | C13: SUP-01 | D13: Yes
A14: 10 | B14: Replace this catalogue with Adithya’s RBAC list once received, or merge the two? | C14: All | D14: Merge: keep IDs, take role defaults from the RBAC list
A15: 11 | B15: FSD v0.3 sets permissions per module (None, View or Edit). That cannot express some defaults here, e.g. a supervisor who views sessions but also creates them. Switch the Create user and Create role screens to permission-level ticks grouped by module? | C15: FSD v0.3 S3, S4; all rows | D15: Yes: ticks per permission, with a module-level ‘select all’
A16: 12 | B16: FSD v0.3 gives the Org Admin no Sessions access, but the agreed Org Admin flow (D-014) has the Org Admin scheduling sessions. Allow scheduling only (SES-01 to SES-05), with no session content? | C16: SES-01 to SES-05; FSD v0.3 2.2 | D16: Yes: schedule only; session records stay hidden
